<robot name="quad2">
   <link name="fixed_base">
      <visual>
          <geometry>
             <box size="0.4 0.8 0.2"/>
          </geometry>
          <material name="red">
             <color rgba="0.8 0 0 1"/>
          </material>
          <origin xyz="0 0 0.55"/>
      </visual>
    </link>

    <link name="link1">
       <visual>
           <geometry>
               <cylinder radius="0.05" length="0.35"/>
           </geometry>
           <material name="white">
               <color rgba="0.8 0.8 0.8 1"/>
           </material>
           <origin xyz="0.15 0.2 0.35" rpy="1 0 0"/>
       </visual>
    </link>

    <link name="link2">
       <visual>
           <geometry>
               <cylinder radius="0.05" length="0.35"/>
           </geometry>
           <material name="white">
               <color rgba="0.8 0.8 0.8 1"/>
           </material>
           <origin xyz="0.15 -0.2 0.35" rpy="1 0 0"/>
       </visual>
    </link>

    <link name="link3">
       <visual>
           <geometry>
               <cylinder radius="0.05" length="0.35"/>
           </geometry>
           <material name="white">
               <color rgba="0.8 0.8 0.8 1"/>
           </material>
           <origin xyz="-0.15 0.2 0.35" rpy="1 0 0"/>
       </visual>
    </link>

    <link name="link4">
       <visual>
           <geometry>
               <cylinder radius="0.05" length="0.35"/>
           </geometry>
           <material name="white">
               <color rgba="0.8 0.8 0.8 1"/>
           </material>
           <origin xyz="-0.15 -0.2 0.35" rpy="1 0 0"/>
       </visual>
    </link>

    <link name="link1_1">
       <visual>
           <geometry>
               <cylinder radius="0.05" length="0.35"/>
           </geometry>
           <material name="blue">
               <color rgba="0 0 0.8 1"/>
           </material>
           <origin xyz="0.15 0.2 0.15" rpy="-1 0 0"/>
       </visual>
    </link>

    <link name="link2_1">
       <visual>
           <geometry>
               <cylinder radius="0.05" length="0.35"/>
           </geometry>
           <material name="blue">
               <color rgba="0 0 0.8 1"/>
           </material>
           <origin xyz="0.15 -0.2 0.15" rpy="-1 0 0"/>
       </visual>
    </link>

    <link name="link3_1">
       <visual>
           <geometry>
               <cylinder radius="0.05" length="0.35"/>
           </geometry>
           <material name="blue">
               <color rgba="0 0 0.8 1"/>
           </material>
           <origin xyz="-0.15 0.2 0.15" rpy="-1 0 0"/>
       </visual>
    </link>

    <link name="link4_1">
       <visual>
           <geometry>
               <cylinder radius="0.05" length="0.35"/>
           </geometry>
           <material name="blue">
               <color rgba="0 0 0.8 1"/>
           </material>
           <origin xyz="-0.15 -0.2 0.15" rpy="-1 0 0"/>
       </visual>
    </link>

    <joint name="Revolute_joint_1" type="revolute">
       <parent link="fixed_base"/>
       <child link="link1"/>
       <origin rpy="0 0 0" xyz="0 0 0"/>
       <axis xyz="1 0 0"/>
       <limit effort="1000.0" lower="-1.57" upper="1.57" velocity="0.5"/>
    </joint>

    <joint name="Revolute_joint_2" type="revolute">
       <parent link="fixed_base"/>
       <child link="link2"/>
       <origin rpy="0 0 0" xyz="0 0 0"/>
       <axis xyz="1 0 0"/>
       <limit effort="1000.0" lower="-1.57" upper="1.57" velocity="0.5"/>
    </joint>

    <joint name="Revolute_joint_3" type="revolute">
       <parent link="fixed_base"/>
       <child link="link3"/>
       <origin rpy="0 0 0" xyz="0 0 0"/>
       <axis xyz="1 0 0"/>
       <limit effort="1000.0" lower="-1.57" upper="1.57" velocity="0.5"/>
    </joint>

    <joint name="Revolute_joint_4" type="revolute">
       <parent link="fixed_base"/>
       <child link="link4"/>
       <origin rpy="0 0 0" xyz="0 0 0"/>
       <axis xyz="1 0 0"/>
       <limit effort="1000.0" lower="-1.57" upper="1.57" velocity="0.5"/>
    </joint>

    <joint name="Revolute_joint_1_1" type="revolute">
       <parent link="link1"/>
       <child link="link1_1"/>
       <origin rpy="0 0 0" xyz="0 0 0"/>
       <axis xyz="1 0 0"/>
       <limit effort="1000.0" lower="-1.57" upper="1.57" velocity="0.5"/>
    </joint>

    <joint name="Revolute_joint_2_1" type="revolute">
       <parent link="link2"/>
       <child link="link2_1"/>
       <origin rpy="0 0 0" xyz="0 0 0"/>
       <axis xyz="1 0 0"/>
       <limit effort="1000.0" lower="-1.57" upper="1.57" velocity="0.5"/>
    </joint>

    <joint name="Revolute_joint_3_1" type="revolute">
       <parent link="link3"/>
       <child link="link3_1"/>
       <origin rpy="0 0 0" xyz="0 0 0"/>
       <axis xyz="1 0 0"/>
       <limit effort="1000.0" lower="-1.57" upper="1.57" velocity="0.5"/>
    </joint>

    <joint name="Revolute_joint_4_1" type="revolute">
       <parent link="link4"/>
       <child link="link4_1"/>
       <origin rpy="0 0 0" xyz="0 0 0"/>
       <axis xyz="1 0 0"/>
       <limit effort="1000.0" lower="-1.57" upper="1.57" velocity="0.5"/>
    </joint>

</robot>
